[2024-05-25T15:48:44.775+0000] {local_task_job_runner.py:120} INFO - ::group::Pre task execution logs
[2024-05-25T15:48:44.794+0000] {taskinstance.py:2076} INFO - Dependencies all met for dep_context=non-requeueable deps ti=<TaskInstance: twitter_etl.get_twitter_data manual__2024-05-25T15:48:43.592522+00:00 [queued]>
[2024-05-25T15:48:44.829+0000] {taskinstance.py:2076} INFO - Dependencies all met for dep_context=requeueable deps ti=<TaskInstance: twitter_etl.get_twitter_data manual__2024-05-25T15:48:43.592522+00:00 [queued]>
[2024-05-25T15:48:44.829+0000] {taskinstance.py:2306} INFO - Starting attempt 1 of 1
[2024-05-25T15:48:44.843+0000] {taskinstance.py:2330} INFO - Executing <Task(_PythonDecoratedOperator): get_twitter_data> on 2024-05-25 15:48:43.592522+00:00
[2024-05-25T15:48:44.848+0000] {warnings.py:110} WARNING - /home/***/.local/lib/python3.12/site-packages/***/task/task_runner/standard_task_runner.py:61: DeprecationWarning: This process (pid=234) is multi-threaded, use of fork() may lead to deadlocks in the child.
  pid = os.fork()

[2024-05-25T15:48:44.849+0000] {standard_task_runner.py:63} INFO - Started process 235 to run task
[2024-05-25T15:48:44.849+0000] {standard_task_runner.py:90} INFO - Running: ['***', 'tasks', 'run', 'twitter_etl', 'get_twitter_data', 'manual__2024-05-25T15:48:43.592522+00:00', '--job-id', '159', '--raw', '--subdir', 'DAGS_FOLDER/csv_copy_to_mino_dag.py', '--cfg-path', '/tmp/tmpllsw1uzd']
[2024-05-25T15:48:44.850+0000] {standard_task_runner.py:91} INFO - Job 159: Subtask get_twitter_data
[2024-05-25T15:48:44.885+0000] {task_command.py:426} INFO - Running <TaskInstance: twitter_etl.get_twitter_data manual__2024-05-25T15:48:43.592522+00:00 [running]> on host fd6401a86447
[2024-05-25T15:48:44.956+0000] {taskinstance.py:2648} INFO - Exporting env vars: AIRFLOW_CTX_DAG_OWNER='***' AIRFLOW_CTX_DAG_ID='twitter_etl' AIRFLOW_CTX_TASK_ID='get_twitter_data' AIRFLOW_CTX_EXECUTION_DATE='2024-05-25T15:48:43.592522+00:00' AIRFLOW_CTX_TRY_NUMBER='1' AIRFLOW_CTX_DAG_RUN_ID='manual__2024-05-25T15:48:43.592522+00:00'
[2024-05-25T15:48:44.957+0000] {taskinstance.py:430} INFO - ::endgroup::
[2024-05-25T15:48:45.572+0000] {taskinstance.py:441} INFO - ::group::Post task execution logs
[2024-05-25T15:48:45.573+0000] {taskinstance.py:2905} ERROR - Task failed with exception
Traceback (most recent call last):
  File "/home/airflow/.local/lib/python3.12/site-packages/airflow/models/taskinstance.py", line 465, in _execute_task
    result = _execute_callable(context=context, **execute_callable_kwargs)
             ^^^^^^^^^^^^^^^^^^^^^^^^^^^^^^^^^^^^^^^^^^^^^^^^^^^^^^^^^^^^^
  File "/home/airflow/.local/lib/python3.12/site-packages/airflow/models/taskinstance.py", line 432, in _execute_callable
    return execute_callable(context=context, **execute_callable_kwargs)
           ^^^^^^^^^^^^^^^^^^^^^^^^^^^^^^^^^^^^^^^^^^^^^^^^^^^^^^^^^^^^
  File "/home/airflow/.local/lib/python3.12/site-packages/airflow/models/baseoperator.py", line 400, in wrapper
    return func(self, *args, **kwargs)
           ^^^^^^^^^^^^^^^^^^^^^^^^^^^
  File "/home/airflow/.local/lib/python3.12/site-packages/airflow/decorators/base.py", line 265, in execute
    return_value = super().execute(context)
                   ^^^^^^^^^^^^^^^^^^^^^^^^
  File "/home/airflow/.local/lib/python3.12/site-packages/airflow/models/baseoperator.py", line 400, in wrapper
    return func(self, *args, **kwargs)
           ^^^^^^^^^^^^^^^^^^^^^^^^^^^
  File "/home/airflow/.local/lib/python3.12/site-packages/airflow/operators/python.py", line 235, in execute
    return_value = self.execute_callable()
                   ^^^^^^^^^^^^^^^^^^^^^^^
  File "/home/airflow/.local/lib/python3.12/site-packages/airflow/operators/python.py", line 252, in execute_callable
    return self.python_callable(*self.op_args, **self.op_kwargs)
           ^^^^^^^^^^^^^^^^^^^^^^^^^^^^^^^^^^^^^^^^^^^^^^^^^^^^^
  File "/opt/airflow/dags/csv_copy_to_mino_dag.py", line 21, in get_twitter_data
    data = response["data"]
           ~~~~~~~~^^^^^^^^
KeyError: 'data'
[2024-05-25T15:48:45.582+0000] {taskinstance.py:1206} INFO - Marking task as FAILED. dag_id=twitter_etl, task_id=get_twitter_data, run_id=manual__2024-05-25T15:48:43.592522+00:00, execution_date=20240525T154843, start_date=20240525T154844, end_date=20240525T154845
[2024-05-25T15:48:45.590+0000] {standard_task_runner.py:110} ERROR - Failed to execute job 159 for task get_twitter_data ('data'; 235)
[2024-05-25T15:48:45.626+0000] {local_task_job_runner.py:240} INFO - Task exited with return code 1
[2024-05-25T15:48:45.642+0000] {taskinstance.py:3498} INFO - 0 downstream tasks scheduled from follow-on schedule check
[2024-05-25T15:48:45.647+0000] {local_task_job_runner.py:222} INFO - ::endgroup::
