[2024-05-25T13:16:12.786+0000] {task_context_logger.py:104} ERROR - Executor reports task instance <TaskInstance: csv_to_minio_dag.dump_data_to_bucket manual__2024-05-25T13:16:10.552940+00:00 [queued]> finished (failed) although the task says it's queued. (Info: None) Was the task killed externally?
