[2024-05-25T13:16:10.576+0000] {task_context_logger.py:104} ERROR - Executor reports task instance <TaskInstance: csv_to_minio_dag.dump_data_to_bucket scheduled__2024-05-24T00:00:00+00:00 [queued]> finished (failed) although the task says it's queued. (Info: None) Was the task killed externally?
