[2024-06-02T12:26:11.545+0000] {task_context_logger.py:104} ERROR - Executor reports task instance <TaskInstance: copy_csv_to_minio.upload_files_to_minio manual__2024-06-02T12:26:09.800523+00:00 [queued]> finished (failed) although the task says it's queued. (Info: None) Was the task killed externally?
