[2024-05-25T14:44:37.611+0000] {local_task_job_runner.py:120} INFO - ::group::Pre task execution logs
[2024-05-25T14:44:37.624+0000] {taskinstance.py:2076} INFO - Dependencies all met for dep_context=non-requeueable deps ti=<TaskInstance: upload_csv_to_minio.upload_csv_to_minio_task manual__2024-05-25T14:44:36.201666+00:00 [queued]>
[2024-05-25T14:44:37.630+0000] {taskinstance.py:2076} INFO - Dependencies all met for dep_context=requeueable deps ti=<TaskInstance: upload_csv_to_minio.upload_csv_to_minio_task manual__2024-05-25T14:44:36.201666+00:00 [queued]>
[2024-05-25T14:44:37.631+0000] {taskinstance.py:2306} INFO - Starting attempt 1 of 2
[2024-05-25T14:44:37.642+0000] {taskinstance.py:2330} INFO - Executing <Task(PythonOperator): upload_csv_to_minio_task> on 2024-05-25 14:44:36.201666+00:00
[2024-05-25T14:44:37.646+0000] {warnings.py:110} WARNING - /home/***/.local/lib/python3.12/site-packages/***/task/task_runner/standard_task_runner.py:61: DeprecationWarning: This process (pid=202) is multi-threaded, use of fork() may lead to deadlocks in the child.
  pid = os.fork()

[2024-05-25T14:44:37.647+0000] {standard_task_runner.py:63} INFO - Started process 203 to run task
[2024-05-25T14:44:37.647+0000] {standard_task_runner.py:90} INFO - Running: ['***', 'tasks', 'run', 'upload_csv_to_minio', 'upload_csv_to_minio_task', 'manual__2024-05-25T14:44:36.201666+00:00', '--job-id', '97', '--raw', '--subdir', 'DAGS_FOLDER/csv_copy_to_mino_dag.py', '--cfg-path', '/tmp/tmpz4dqcgcu']
[2024-05-25T14:44:37.648+0000] {standard_task_runner.py:91} INFO - Job 97: Subtask upload_csv_to_minio_task
[2024-05-25T14:44:37.681+0000] {task_command.py:426} INFO - Running <TaskInstance: upload_csv_to_minio.upload_csv_to_minio_task manual__2024-05-25T14:44:36.201666+00:00 [running]> on host ef97b3be753c
[2024-05-25T14:44:37.739+0000] {taskinstance.py:2648} INFO - Exporting env vars: AIRFLOW_CTX_DAG_OWNER='***' AIRFLOW_CTX_DAG_ID='upload_csv_to_minio' AIRFLOW_CTX_TASK_ID='upload_csv_to_minio_task' AIRFLOW_CTX_EXECUTION_DATE='2024-05-25T14:44:36.201666+00:00' AIRFLOW_CTX_TRY_NUMBER='1' AIRFLOW_CTX_DAG_RUN_ID='manual__2024-05-25T14:44:36.201666+00:00'
[2024-05-25T14:44:37.740+0000] {taskinstance.py:430} INFO - ::endgroup::
[2024-05-25T14:44:37.755+0000] {base.py:84} INFO - Using connection ID 'minio_s3' for task execution.
[2024-05-25T14:44:37.756+0000] {connection_wrapper.py:387} INFO - AWS Connection (conn_id='minio_s3', conn_type='aws') credentials retrieved from extra.
[2024-05-25T14:44:37.757+0000] {warnings.py:110} WARNING - <string>:9: AirflowProviderDeprecationWarning: extra['host'] is deprecated and will be removed in a future release. Please set extra['endpoint_url'] instead

[2024-05-25T14:44:43.753+0000] {taskinstance.py:441} INFO - ::group::Post task execution logs
[2024-05-25T14:44:43.756+0000] {taskinstance.py:2905} ERROR - Task failed with exception
Traceback (most recent call last):
  File "/home/airflow/.local/lib/python3.12/site-packages/urllib3/connection.py", line 198, in _new_conn
    sock = connection.create_connection(
           ^^^^^^^^^^^^^^^^^^^^^^^^^^^^^
  File "/home/airflow/.local/lib/python3.12/site-packages/urllib3/util/connection.py", line 85, in create_connection
    raise err
  File "/home/airflow/.local/lib/python3.12/site-packages/urllib3/util/connection.py", line 73, in create_connection
    sock.connect(sa)
ConnectionRefusedError: [Errno 111] Connection refused

The above exception was the direct cause of the following exception:

Traceback (most recent call last):
  File "/home/airflow/.local/lib/python3.12/site-packages/botocore/httpsession.py", line 464, in send
    urllib_response = conn.urlopen(
                      ^^^^^^^^^^^^^
  File "/home/airflow/.local/lib/python3.12/site-packages/urllib3/connectionpool.py", line 847, in urlopen
    retries = retries.increment(
              ^^^^^^^^^^^^^^^^^^
  File "/home/airflow/.local/lib/python3.12/site-packages/urllib3/util/retry.py", line 445, in increment
    raise reraise(type(error), error, _stacktrace)
          ^^^^^^^^^^^^^^^^^^^^^^^^^^^^^^^^^^^^^^^^
  File "/home/airflow/.local/lib/python3.12/site-packages/urllib3/util/util.py", line 39, in reraise
    raise value
  File "/home/airflow/.local/lib/python3.12/site-packages/urllib3/connectionpool.py", line 793, in urlopen
    response = self._make_request(
               ^^^^^^^^^^^^^^^^^^^
  File "/home/airflow/.local/lib/python3.12/site-packages/urllib3/connectionpool.py", line 496, in _make_request
    conn.request(
  File "/home/airflow/.local/lib/python3.12/site-packages/botocore/awsrequest.py", line 96, in request
    rval = super().request(method, url, body, headers, *args, **kwargs)
           ^^^^^^^^^^^^^^^^^^^^^^^^^^^^^^^^^^^^^^^^^^^^^^^^^^^^^^^^^^^^
  File "/home/airflow/.local/lib/python3.12/site-packages/urllib3/connection.py", line 400, in request
    self.endheaders()
  File "/usr/local/lib/python3.12/http/client.py", line 1331, in endheaders
    self._send_output(message_body, encode_chunked=encode_chunked)
  File "/home/airflow/.local/lib/python3.12/site-packages/botocore/awsrequest.py", line 123, in _send_output
    self.send(msg)
  File "/home/airflow/.local/lib/python3.12/site-packages/botocore/awsrequest.py", line 223, in send
    return super().send(str)
           ^^^^^^^^^^^^^^^^^
  File "/usr/local/lib/python3.12/http/client.py", line 1035, in send
    self.connect()
  File "/home/airflow/.local/lib/python3.12/site-packages/urllib3/connection.py", line 238, in connect
    self.sock = self._new_conn()
                ^^^^^^^^^^^^^^^^
  File "/home/airflow/.local/lib/python3.12/site-packages/urllib3/connection.py", line 213, in _new_conn
    raise NewConnectionError(
urllib3.exceptions.NewConnectionError: <botocore.awsrequest.AWSHTTPConnection object at 0x7f707deb67e0>: Failed to establish a new connection: [Errno 111] Connection refused

During handling of the above exception, another exception occurred:

Traceback (most recent call last):
  File "/home/airflow/.local/lib/python3.12/site-packages/airflow/models/taskinstance.py", line 465, in _execute_task
    result = _execute_callable(context=context, **execute_callable_kwargs)
             ^^^^^^^^^^^^^^^^^^^^^^^^^^^^^^^^^^^^^^^^^^^^^^^^^^^^^^^^^^^^^
  File "/home/airflow/.local/lib/python3.12/site-packages/airflow/models/taskinstance.py", line 432, in _execute_callable
    return execute_callable(context=context, **execute_callable_kwargs)
           ^^^^^^^^^^^^^^^^^^^^^^^^^^^^^^^^^^^^^^^^^^^^^^^^^^^^^^^^^^^^
  File "/home/airflow/.local/lib/python3.12/site-packages/airflow/models/baseoperator.py", line 400, in wrapper
    return func(self, *args, **kwargs)
           ^^^^^^^^^^^^^^^^^^^^^^^^^^^
  File "/home/airflow/.local/lib/python3.12/site-packages/airflow/operators/python.py", line 235, in execute
    return_value = self.execute_callable()
                   ^^^^^^^^^^^^^^^^^^^^^^^
  File "/home/airflow/.local/lib/python3.12/site-packages/airflow/operators/python.py", line 252, in execute_callable
    return self.python_callable(*self.op_args, **self.op_kwargs)
           ^^^^^^^^^^^^^^^^^^^^^^^^^^^^^^^^^^^^^^^^^^^^^^^^^^^^^
  File "/opt/airflow/dags/csv_copy_to_mino_dag.py", line 21, in upload_csv_to_minio
    minio_hook.load_file(
  File "/home/airflow/.local/lib/python3.12/site-packages/airflow/providers/amazon/aws/hooks/s3.py", line 135, in wrapper
    return func(*bound_args.args, **bound_args.kwargs)
           ^^^^^^^^^^^^^^^^^^^^^^^^^^^^^^^^^^^^^^^^^^^
  File "/home/airflow/.local/lib/python3.12/site-packages/airflow/providers/amazon/aws/hooks/s3.py", line 89, in wrapper
    return func(*bound_args.args, **bound_args.kwargs)
           ^^^^^^^^^^^^^^^^^^^^^^^^^^^^^^^^^^^^^^^^^^^
  File "/home/airflow/.local/lib/python3.12/site-packages/airflow/providers/amazon/aws/hooks/s3.py", line 1082, in load_file
    if not replace and self.check_for_key(key, bucket_name):
                       ^^^^^^^^^^^^^^^^^^^^^^^^^^^^^^^^^^^^
  File "/home/airflow/.local/lib/python3.12/site-packages/airflow/providers/amazon/aws/hooks/s3.py", line 135, in wrapper
    return func(*bound_args.args, **bound_args.kwargs)
           ^^^^^^^^^^^^^^^^^^^^^^^^^^^^^^^^^^^^^^^^^^^
  File "/home/airflow/.local/lib/python3.12/site-packages/airflow/providers/amazon/aws/hooks/s3.py", line 89, in wrapper
    return func(*bound_args.args, **bound_args.kwargs)
           ^^^^^^^^^^^^^^^^^^^^^^^^^^^^^^^^^^^^^^^^^^^
  File "/home/airflow/.local/lib/python3.12/site-packages/airflow/providers/amazon/aws/hooks/s3.py", line 922, in check_for_key
    obj = self.head_object(key, bucket_name)
          ^^^^^^^^^^^^^^^^^^^^^^^^^^^^^^^^^^
  File "/home/airflow/.local/lib/python3.12/site-packages/airflow/providers/amazon/aws/hooks/s3.py", line 135, in wrapper
    return func(*bound_args.args, **bound_args.kwargs)
           ^^^^^^^^^^^^^^^^^^^^^^^^^^^^^^^^^^^^^^^^^^^
  File "/home/airflow/.local/lib/python3.12/site-packages/airflow/providers/amazon/aws/hooks/s3.py", line 89, in wrapper
    return func(*bound_args.args, **bound_args.kwargs)
           ^^^^^^^^^^^^^^^^^^^^^^^^^^^^^^^^^^^^^^^^^^^
  File "/home/airflow/.local/lib/python3.12/site-packages/airflow/providers/amazon/aws/hooks/s3.py", line 902, in head_object
    return self.get_conn().head_object(Bucket=bucket_name, Key=key)
           ^^^^^^^^^^^^^^^^^^^^^^^^^^^^^^^^^^^^^^^^^^^^^^^^^^^^^^^^
  File "/home/airflow/.local/lib/python3.12/site-packages/botocore/client.py", line 553, in _api_call
    return self._make_api_call(operation_name, kwargs)
           ^^^^^^^^^^^^^^^^^^^^^^^^^^^^^^^^^^^^^^^^^^^
  File "/home/airflow/.local/lib/python3.12/site-packages/botocore/client.py", line 989, in _make_api_call
    http, parsed_response = self._make_request(
                            ^^^^^^^^^^^^^^^^^^^
  File "/home/airflow/.local/lib/python3.12/site-packages/botocore/client.py", line 1015, in _make_request
    return self._endpoint.make_request(operation_model, request_dict)
           ^^^^^^^^^^^^^^^^^^^^^^^^^^^^^^^^^^^^^^^^^^^^^^^^^^^^^^^^^^
  File "/home/airflow/.local/lib/python3.12/site-packages/botocore/endpoint.py", line 119, in make_request
    return self._send_request(request_dict, operation_model)
           ^^^^^^^^^^^^^^^^^^^^^^^^^^^^^^^^^^^^^^^^^^^^^^^^^
  File "/home/airflow/.local/lib/python3.12/site-packages/botocore/endpoint.py", line 202, in _send_request
    while self._needs_retry(
          ^^^^^^^^^^^^^^^^^^
  File "/home/airflow/.local/lib/python3.12/site-packages/botocore/endpoint.py", line 354, in _needs_retry
    responses = self._event_emitter.emit(
                ^^^^^^^^^^^^^^^^^^^^^^^^^
  File "/home/airflow/.local/lib/python3.12/site-packages/botocore/hooks.py", line 412, in emit
    return self._emitter.emit(aliased_event_name, **kwargs)
           ^^^^^^^^^^^^^^^^^^^^^^^^^^^^^^^^^^^^^^^^^^^^^^^^
  File "/home/airflow/.local/lib/python3.12/site-packages/botocore/hooks.py", line 256, in emit
    return self._emit(event_name, kwargs)
           ^^^^^^^^^^^^^^^^^^^^^^^^^^^^^^
  File "/home/airflow/.local/lib/python3.12/site-packages/botocore/hooks.py", line 239, in _emit
    response = handler(**kwargs)
               ^^^^^^^^^^^^^^^^^
  File "/home/airflow/.local/lib/python3.12/site-packages/botocore/retryhandler.py", line 207, in __call__
    if self._checker(**checker_kwargs):
       ^^^^^^^^^^^^^^^^^^^^^^^^^^^^^^^
  File "/home/airflow/.local/lib/python3.12/site-packages/botocore/retryhandler.py", line 284, in __call__
    should_retry = self._should_retry(
                   ^^^^^^^^^^^^^^^^^^^
  File "/home/airflow/.local/lib/python3.12/site-packages/botocore/retryhandler.py", line 320, in _should_retry
    return self._checker(attempt_number, response, caught_exception)
           ^^^^^^^^^^^^^^^^^^^^^^^^^^^^^^^^^^^^^^^^^^^^^^^^^^^^^^^^^
  File "/home/airflow/.local/lib/python3.12/site-packages/botocore/retryhandler.py", line 363, in __call__
    checker_response = checker(
                       ^^^^^^^^
  File "/home/airflow/.local/lib/python3.12/site-packages/botocore/retryhandler.py", line 247, in __call__
    return self._check_caught_exception(
           ^^^^^^^^^^^^^^^^^^^^^^^^^^^^^
  File "/home/airflow/.local/lib/python3.12/site-packages/botocore/retryhandler.py", line 416, in _check_caught_exception
    raise caught_exception
  File "/home/airflow/.local/lib/python3.12/site-packages/botocore/endpoint.py", line 281, in _do_get_response
    http_response = self._send(request)
                    ^^^^^^^^^^^^^^^^^^^
  File "/home/airflow/.local/lib/python3.12/site-packages/botocore/endpoint.py", line 377, in _send
    return self.http_session.send(request)
           ^^^^^^^^^^^^^^^^^^^^^^^^^^^^^^^
  File "/home/airflow/.local/lib/python3.12/site-packages/botocore/httpsession.py", line 493, in send
    raise EndpointConnectionError(endpoint_url=request.url, error=e)
botocore.exceptions.EndpointConnectionError: Could not connect to the endpoint URL: "http://localhost:9090/browser/***-bucket/sample.csv"
[2024-05-25T14:44:43.769+0000] {taskinstance.py:1206} INFO - Marking task as UP_FOR_RETRY. dag_id=upload_csv_to_minio, task_id=upload_csv_to_minio_task, run_id=manual__2024-05-25T14:44:36.201666+00:00, execution_date=20240525T144436, start_date=20240525T144437, end_date=20240525T144443
[2024-05-25T14:44:43.779+0000] {standard_task_runner.py:110} ERROR - Failed to execute job 97 for task upload_csv_to_minio_task (Could not connect to the endpoint URL: "http://localhost:9090/browser/***-bucket/sample.csv"; 203)
[2024-05-25T14:44:43.806+0000] {local_task_job_runner.py:240} INFO - Task exited with return code 1
[2024-05-25T14:44:43.838+0000] {taskinstance.py:3498} INFO - 0 downstream tasks scheduled from follow-on schedule check
[2024-05-25T14:44:43.843+0000] {local_task_job_runner.py:222} INFO - ::endgroup::
