[2024-05-25T13:27:36.693+0000] {task_context_logger.py:104} ERROR - Executor reports task instance <TaskInstance: check_minio_bucket_dag.check_and_create_bucket scheduled__2024-05-24T00:00:00+00:00 [queued]> finished (failed) although the task says it's queued. (Info: None) Was the task killed externally?
