[2024-05-25T14:36:35.849+0000] {local_task_job_runner.py:120} INFO - ::group::Pre task execution logs
[2024-05-25T14:36:35.866+0000] {taskinstance.py:2076} INFO - Dependencies all met for dep_context=non-requeueable deps ti=<TaskInstance: csv_copy_to_minio_dag.copy_csv_to_minio manual__2024-05-25T14:36:22.763185+00:00 [queued]>
[2024-05-25T14:36:35.874+0000] {taskinstance.py:2076} INFO - Dependencies all met for dep_context=requeueable deps ti=<TaskInstance: csv_copy_to_minio_dag.copy_csv_to_minio manual__2024-05-25T14:36:22.763185+00:00 [queued]>
[2024-05-25T14:36:35.875+0000] {taskinstance.py:2306} INFO - Starting attempt 2 of 2
[2024-05-25T14:36:35.891+0000] {taskinstance.py:2330} INFO - Executing <Task(PythonOperator): copy_csv_to_minio> on 2024-05-25 14:36:22.763185+00:00
[2024-05-25T14:36:35.896+0000] {warnings.py:110} WARNING - /home/***/.local/lib/python3.12/site-packages/***/task/task_runner/standard_task_runner.py:61: DeprecationWarning: This process (pid=92) is multi-threaded, use of fork() may lead to deadlocks in the child.
  pid = os.fork()

[2024-05-25T14:36:35.898+0000] {standard_task_runner.py:63} INFO - Started process 93 to run task
[2024-05-25T14:36:35.898+0000] {standard_task_runner.py:90} INFO - Running: ['***', 'tasks', 'run', 'csv_copy_to_minio_dag', 'copy_csv_to_minio', 'manual__2024-05-25T14:36:22.763185+00:00', '--job-id', '94', '--raw', '--subdir', 'DAGS_FOLDER/csv_copy_to_mino_dag.py', '--cfg-path', '/tmp/tmp9w2r163u']
[2024-05-25T14:36:35.899+0000] {standard_task_runner.py:91} INFO - Job 94: Subtask copy_csv_to_minio
[2024-05-25T14:36:35.940+0000] {task_command.py:426} INFO - Running <TaskInstance: csv_copy_to_minio_dag.copy_csv_to_minio manual__2024-05-25T14:36:22.763185+00:00 [running]> on host ef97b3be753c
[2024-05-25T14:36:36.016+0000] {taskinstance.py:2648} INFO - Exporting env vars: AIRFLOW_CTX_DAG_OWNER='***' AIRFLOW_CTX_DAG_ID='csv_copy_to_minio_dag' AIRFLOW_CTX_TASK_ID='copy_csv_to_minio' AIRFLOW_CTX_EXECUTION_DATE='2024-05-25T14:36:22.763185+00:00' AIRFLOW_CTX_TRY_NUMBER='2' AIRFLOW_CTX_DAG_RUN_ID='manual__2024-05-25T14:36:22.763185+00:00'
[2024-05-25T14:36:36.017+0000] {taskinstance.py:430} INFO - ::endgroup::
[2024-05-25T14:36:36.038+0000] {base.py:84} INFO - Using connection ID 'minio_s3' for task execution.
[2024-05-25T14:36:36.039+0000] {connection_wrapper.py:387} INFO - AWS Connection (conn_id='minio_s3', conn_type='aws') credentials retrieved from extra.
[2024-05-25T14:36:36.039+0000] {warnings.py:110} WARNING - <string>:9: AirflowProviderDeprecationWarning: extra['host'] is deprecated and will be removed in a future release. Please set extra['endpoint_url'] instead

[2024-05-25T14:36:45.491+0000] {taskinstance.py:441} INFO - ::group::Post task execution logs
[2024-05-25T14:36:45.492+0000] {taskinstance.py:2905} ERROR - Task failed with exception
Traceback (most recent call last):
  File "/home/airflow/.local/lib/python3.12/site-packages/urllib3/connection.py", line 198, in _new_conn
    sock = connection.create_connection(
           ^^^^^^^^^^^^^^^^^^^^^^^^^^^^^
  File "/home/airflow/.local/lib/python3.12/site-packages/urllib3/util/connection.py", line 85, in create_connection
    raise err
  File "/home/airflow/.local/lib/python3.12/site-packages/urllib3/util/connection.py", line 73, in create_connection
    sock.connect(sa)
ConnectionRefusedError: [Errno 111] Connection refused

The above exception was the direct cause of the following exception:

Traceback (most recent call last):
  File "/home/airflow/.local/lib/python3.12/site-packages/botocore/httpsession.py", line 464, in send
    urllib_response = conn.urlopen(
                      ^^^^^^^^^^^^^
  File "/home/airflow/.local/lib/python3.12/site-packages/urllib3/connectionpool.py", line 847, in urlopen
    retries = retries.increment(
              ^^^^^^^^^^^^^^^^^^
  File "/home/airflow/.local/lib/python3.12/site-packages/urllib3/util/retry.py", line 445, in increment
    raise reraise(type(error), error, _stacktrace)
          ^^^^^^^^^^^^^^^^^^^^^^^^^^^^^^^^^^^^^^^^
  File "/home/airflow/.local/lib/python3.12/site-packages/urllib3/util/util.py", line 39, in reraise
    raise value
  File "/home/airflow/.local/lib/python3.12/site-packages/urllib3/connectionpool.py", line 793, in urlopen
    response = self._make_request(
               ^^^^^^^^^^^^^^^^^^^
  File "/home/airflow/.local/lib/python3.12/site-packages/urllib3/connectionpool.py", line 496, in _make_request
    conn.request(
  File "/home/airflow/.local/lib/python3.12/site-packages/botocore/awsrequest.py", line 96, in request
    rval = super().request(method, url, body, headers, *args, **kwargs)
           ^^^^^^^^^^^^^^^^^^^^^^^^^^^^^^^^^^^^^^^^^^^^^^^^^^^^^^^^^^^^
  File "/home/airflow/.local/lib/python3.12/site-packages/urllib3/connection.py", line 400, in request
    self.endheaders()
  File "/usr/local/lib/python3.12/http/client.py", line 1331, in endheaders
    self._send_output(message_body, encode_chunked=encode_chunked)
  File "/home/airflow/.local/lib/python3.12/site-packages/botocore/awsrequest.py", line 123, in _send_output
    self.send(msg)
  File "/home/airflow/.local/lib/python3.12/site-packages/botocore/awsrequest.py", line 223, in send
    return super().send(str)
           ^^^^^^^^^^^^^^^^^
  File "/usr/local/lib/python3.12/http/client.py", line 1035, in send
    self.connect()
  File "/home/airflow/.local/lib/python3.12/site-packages/urllib3/connection.py", line 238, in connect
    self.sock = self._new_conn()
                ^^^^^^^^^^^^^^^^
  File "/home/airflow/.local/lib/python3.12/site-packages/urllib3/connection.py", line 213, in _new_conn
    raise NewConnectionError(
urllib3.exceptions.NewConnectionError: <botocore.awsrequest.AWSHTTPConnection object at 0x7f707debaea0>: Failed to establish a new connection: [Errno 111] Connection refused

During handling of the above exception, another exception occurred:

Traceback (most recent call last):
  File "/home/airflow/.local/lib/python3.12/site-packages/airflow/models/taskinstance.py", line 465, in _execute_task
    result = _execute_callable(context=context, **execute_callable_kwargs)
             ^^^^^^^^^^^^^^^^^^^^^^^^^^^^^^^^^^^^^^^^^^^^^^^^^^^^^^^^^^^^^
  File "/home/airflow/.local/lib/python3.12/site-packages/airflow/models/taskinstance.py", line 432, in _execute_callable
    return execute_callable(context=context, **execute_callable_kwargs)
           ^^^^^^^^^^^^^^^^^^^^^^^^^^^^^^^^^^^^^^^^^^^^^^^^^^^^^^^^^^^^
  File "/home/airflow/.local/lib/python3.12/site-packages/airflow/models/baseoperator.py", line 400, in wrapper
    return func(self, *args, **kwargs)
           ^^^^^^^^^^^^^^^^^^^^^^^^^^^
  File "/home/airflow/.local/lib/python3.12/site-packages/airflow/operators/python.py", line 235, in execute
    return_value = self.execute_callable()
                   ^^^^^^^^^^^^^^^^^^^^^^^
  File "/home/airflow/.local/lib/python3.12/site-packages/airflow/operators/python.py", line 252, in execute_callable
    return self.python_callable(*self.op_args, **self.op_kwargs)
           ^^^^^^^^^^^^^^^^^^^^^^^^^^^^^^^^^^^^^^^^^^^^^^^^^^^^^
  File "/opt/airflow/dags/csv_copy_to_mino_dag.py", line 39, in copy_csv_to_minio
    s3_hook.load_file(
  File "/home/airflow/.local/lib/python3.12/site-packages/airflow/providers/amazon/aws/hooks/s3.py", line 135, in wrapper
    return func(*bound_args.args, **bound_args.kwargs)
           ^^^^^^^^^^^^^^^^^^^^^^^^^^^^^^^^^^^^^^^^^^^
  File "/home/airflow/.local/lib/python3.12/site-packages/airflow/providers/amazon/aws/hooks/s3.py", line 89, in wrapper
    return func(*bound_args.args, **bound_args.kwargs)
           ^^^^^^^^^^^^^^^^^^^^^^^^^^^^^^^^^^^^^^^^^^^
  File "/home/airflow/.local/lib/python3.12/site-packages/airflow/providers/amazon/aws/hooks/s3.py", line 1098, in load_file
    client.upload_file(filename, bucket_name, key, ExtraArgs=extra_args, Config=self.transfer_config)
  File "/home/airflow/.local/lib/python3.12/site-packages/boto3/s3/inject.py", line 145, in upload_file
    return transfer.upload_file(
           ^^^^^^^^^^^^^^^^^^^^^
  File "/home/airflow/.local/lib/python3.12/site-packages/boto3/s3/transfer.py", line 371, in upload_file
    future.result()
  File "/home/airflow/.local/lib/python3.12/site-packages/s3transfer/futures.py", line 103, in result
    return self._coordinator.result()
           ^^^^^^^^^^^^^^^^^^^^^^^^^^
  File "/home/airflow/.local/lib/python3.12/site-packages/s3transfer/futures.py", line 266, in result
    raise self._exception
  File "/home/airflow/.local/lib/python3.12/site-packages/s3transfer/tasks.py", line 139, in __call__
    return self._execute_main(kwargs)
           ^^^^^^^^^^^^^^^^^^^^^^^^^^
  File "/home/airflow/.local/lib/python3.12/site-packages/s3transfer/tasks.py", line 162, in _execute_main
    return_value = self._main(**kwargs)
                   ^^^^^^^^^^^^^^^^^^^^
  File "/home/airflow/.local/lib/python3.12/site-packages/s3transfer/upload.py", line 764, in _main
    client.put_object(Bucket=bucket, Key=key, Body=body, **extra_args)
  File "/home/airflow/.local/lib/python3.12/site-packages/botocore/client.py", line 553, in _api_call
    return self._make_api_call(operation_name, kwargs)
           ^^^^^^^^^^^^^^^^^^^^^^^^^^^^^^^^^^^^^^^^^^^
  File "/home/airflow/.local/lib/python3.12/site-packages/botocore/client.py", line 989, in _make_api_call
    http, parsed_response = self._make_request(
                            ^^^^^^^^^^^^^^^^^^^
  File "/home/airflow/.local/lib/python3.12/site-packages/botocore/client.py", line 1015, in _make_request
    return self._endpoint.make_request(operation_model, request_dict)
           ^^^^^^^^^^^^^^^^^^^^^^^^^^^^^^^^^^^^^^^^^^^^^^^^^^^^^^^^^^
  File "/home/airflow/.local/lib/python3.12/site-packages/botocore/endpoint.py", line 119, in make_request
    return self._send_request(request_dict, operation_model)
           ^^^^^^^^^^^^^^^^^^^^^^^^^^^^^^^^^^^^^^^^^^^^^^^^^
  File "/home/airflow/.local/lib/python3.12/site-packages/botocore/endpoint.py", line 202, in _send_request
    while self._needs_retry(
          ^^^^^^^^^^^^^^^^^^
  File "/home/airflow/.local/lib/python3.12/site-packages/botocore/endpoint.py", line 354, in _needs_retry
    responses = self._event_emitter.emit(
                ^^^^^^^^^^^^^^^^^^^^^^^^^
  File "/home/airflow/.local/lib/python3.12/site-packages/botocore/hooks.py", line 412, in emit
    return self._emitter.emit(aliased_event_name, **kwargs)
           ^^^^^^^^^^^^^^^^^^^^^^^^^^^^^^^^^^^^^^^^^^^^^^^^
  File "/home/airflow/.local/lib/python3.12/site-packages/botocore/hooks.py", line 256, in emit
    return self._emit(event_name, kwargs)
           ^^^^^^^^^^^^^^^^^^^^^^^^^^^^^^
  File "/home/airflow/.local/lib/python3.12/site-packages/botocore/hooks.py", line 239, in _emit
    response = handler(**kwargs)
               ^^^^^^^^^^^^^^^^^
  File "/home/airflow/.local/lib/python3.12/site-packages/botocore/retryhandler.py", line 207, in __call__
    if self._checker(**checker_kwargs):
       ^^^^^^^^^^^^^^^^^^^^^^^^^^^^^^^
  File "/home/airflow/.local/lib/python3.12/site-packages/botocore/retryhandler.py", line 284, in __call__
    should_retry = self._should_retry(
                   ^^^^^^^^^^^^^^^^^^^
  File "/home/airflow/.local/lib/python3.12/site-packages/botocore/retryhandler.py", line 320, in _should_retry
    return self._checker(attempt_number, response, caught_exception)
           ^^^^^^^^^^^^^^^^^^^^^^^^^^^^^^^^^^^^^^^^^^^^^^^^^^^^^^^^^
  File "/home/airflow/.local/lib/python3.12/site-packages/botocore/retryhandler.py", line 363, in __call__
    checker_response = checker(
                       ^^^^^^^^
  File "/home/airflow/.local/lib/python3.12/site-packages/botocore/retryhandler.py", line 247, in __call__
    return self._check_caught_exception(
           ^^^^^^^^^^^^^^^^^^^^^^^^^^^^^
  File "/home/airflow/.local/lib/python3.12/site-packages/botocore/retryhandler.py", line 416, in _check_caught_exception
    raise caught_exception
  File "/home/airflow/.local/lib/python3.12/site-packages/botocore/endpoint.py", line 281, in _do_get_response
    http_response = self._send(request)
                    ^^^^^^^^^^^^^^^^^^^
  File "/home/airflow/.local/lib/python3.12/site-packages/botocore/endpoint.py", line 377, in _send
    return self.http_session.send(request)
           ^^^^^^^^^^^^^^^^^^^^^^^^^^^^^^^
  File "/home/airflow/.local/lib/python3.12/site-packages/botocore/httpsession.py", line 493, in send
    raise EndpointConnectionError(endpoint_url=request.url, error=e)
botocore.exceptions.EndpointConnectionError: Could not connect to the endpoint URL: "http://localhost:9090/browser/***-bucket/sample.csv"
[2024-05-25T14:36:45.504+0000] {taskinstance.py:1206} INFO - Marking task as FAILED. dag_id=csv_copy_to_minio_dag, task_id=copy_csv_to_minio, run_id=manual__2024-05-25T14:36:22.763185+00:00, execution_date=20240525T143622, start_date=20240525T143635, end_date=20240525T143645
[2024-05-25T14:36:45.514+0000] {standard_task_runner.py:110} ERROR - Failed to execute job 94 for task copy_csv_to_minio (Could not connect to the endpoint URL: "http://localhost:9090/browser/***-bucket/sample.csv"; 93)
[2024-05-25T14:36:45.554+0000] {local_task_job_runner.py:240} INFO - Task exited with return code 1
[2024-05-25T14:36:45.566+0000] {taskinstance.py:3498} INFO - 0 downstream tasks scheduled from follow-on schedule check
[2024-05-25T14:36:45.568+0000] {local_task_job_runner.py:222} INFO - ::endgroup::
